Workbook

Sheet Mode d’emploi
A1: Suivi de la recette (UAT) — Gestion des frais de fonctionnement
A2: Cahier de recette IGE-AF-REC-001 v1.0 · application 2.2.1 · 51 scénarios, 235 étapes
A4: Onglets
A5: Testeurs | B5: Nom et e-mail de la personne qui joue chaque profil de test.
A6: Exécution | B6: Une ligne par étape. Le testeur renseigne les colonnes jaunes : Statut, Résultat obtenu / commentaire, Réf. anomalie, Testeur, Date.
A7: Anomalies | B7: Registre des anomalies : une ligne par anomalie ouverte (voir l’exemple ci-dessous).
A8: Synthèse scénarios | B8: Calculée automatiquement : nombre d’étapes OK, KO, bloquées, non testées et statut de chaque scénario.
A9: Tableau de bord | B9: Calculé automatiquement : avancement global, par phase, anomalies et critères de sortie de la recette.
A10: Valeurs du statut d’une étape
A11: Non testé | B11: Étape pas encore exécutée (valeur de départ).
A12: OK | B12: Résultat obtenu conforme au résultat attendu.
A13: KO | B13: Résultat différent : décrire l’écart dans « Résultat obtenu » et ouvrir une anomalie.
A14: Bloqué | B14: Étape impossible à exécuter (anomalie précédente, prérequis manquant).
A15: Gravité des anomalies
A16: Bloquante | B16: Empêche une fonction essentielle ou fausse les comptes, sans contournement.
A17: Majeure | B17: Fonction importante incorrecte, contournement pénible ou risqué.
A18: Mineure | B18: Défaut sans impact sur les comptes ni sur la sécurité.
A19: Évolution | B19: Besoin nouveau, non prévu dans l’expression des besoins.
A20: Exemple de ligne d’anomalie
A21: Réf. / scénario / étape | B21: ANO-001 · UAT-17 · étape 3
A22: Description | B22: Paiement en espèces de 2 100 000 accepté sans message.
A23: Attendu / obtenu | B23: Attendu : refus « Paiement en espèces limité à 2 000 000 CDF ». Obtenu : écriture enregistrée.
A24: Gravité / statut | B24: Majeure · Ouverte
A25: Règles
A26: Cellules jaunes | B26: Seules cellules à remplir. Les autres colonnes et onglets calculés ne se modifient pas.
A27: Critères de sortie | B27: 100 % des scénarios critiques OK ; aucune anomalie bloquante ou majeure ouverte ; au moins 95 % des étapes OK.
A29: Exemple de cellule à remplir

Sheet Tableau de bord
A1: Tableau de bord de la recette
A2: Calculé automatiquement · ne rien saisir dans cet onglet
A4: Avancement global
A5: Étapes prévues | B5: =COUNTA(Exécution!$A$5:$A$239) -> 235
A6: Étapes exécutées | B6: =COUNTA(Exécution!$I$5:$I$239)-COUNTIF(Exécution!$I$5:$I$239,"Non testé") -> 0
A7: Étapes OK | B7: =COUNTIF(Exécution!$I$5:$I$239,"OK") -> 0
A8: Étapes KO | B8: =COUNTIF(Exécution!$I$5:$I$239,"KO") -> 0
A9: Étapes bloquées | B9: =COUNTIF(Exécution!$I$5:$I$239,"Bloqué") -> 0
A10: Taux d’exécution | B10: =IF(B5=0,0,B6/B5) -> 0
A11: Taux d’étapes OK (sur les prévues) | B11: =IF(B5=0,0,B7/B5) -> 0
A12: Scénarios OK / prévus | B12: =COUNTIF('Synthèse scénarios'!$J$5:$J$55,"OK") -> 0 | C12: =COUNTA('Synthèse scénarios'!$A$5:$A$55) -> 51 | D12: scénarios
A13: Scénarios critiques OK | B13: =COUNTIFS('Synthèse scénarios'!$D$5:$D$55,"Critique",'Synthèse scénarios'!$J$5:$J$55,"OK") -> 0
A14: Scénarios critiques prévus | B14: =COUNTIF('Synthèse scénarios'!$D$5:$D$55,"Critique") -> 16
A16: Avancement par phase
A17: Phase | B17: Étapes | C17: OK | D17: KO | E17: Bloqué | F17: Non testé | G17: % OK
A18: Préparation de l’environnement | B18: =COUNTIF(Exécution!$B$5:$B$239,A18) -> 22 | C18: =COUNTIFS(Exécution!$B$5:$B$239,$A18,Exécution!$I$5:$I$239,"OK") -> 0 | D18: =COUNTIFS(Exécution!$B$5:$B$239,$A18,Exécution!$I$5:$I$239,"KO") -> 0 | E18: =COUNTIFS(Exécution!$B$5:$B$239,$A18,Exécution!$I$5:$I$239,"Bloqué") -> 0 | F18: =COUNTIFS(Exécution!$B$5:$B$239,$A18,Exécution!$I$5:$I$239,"Non testé") -> 22 | G18: =IF(B18=0,0,C18/B18) -> 0
A19: Accès et sécurité | B19: =COUNTIF(Exécution!$B$5:$B$239,A19) -> 22 | C19: =COUNTIFS(Exécution!$B$5:$B$239,$A19,Exécution!$I$5:$I$239,"OK") -> 0 | D19: =COUNTIFS(Exécution!$B$5:$B$239,$A19,Exécution!$I$5:$I$239,"KO") -> 0 | E19: =COUNTIFS(Exécution!$B$5:$B$239,$A19,Exécution!$I$5:$I$239,"Bloqué") -> 0 | F19: =COUNTIFS(Exécution!$B$5:$B$239,$A19,Exécution!$I$5:$I$239,"Non testé") -> 22 | G19: =IF(B19=0,0,C19/B19) -> 0
A20: Budget et fonds | B20: =COUNTIF(Exécution!$B$5:$B$239,A20) -> 23 | C20: =COUNTIFS(Exécution!$B$5:$B$239,$A20,Exécution!$I$5:$I$239,"OK") -> 0 | D20: =COUNTIFS(Exécution!$B$5:$B$239,$A20,Exécution!$I$5:$I$239,"KO") -> 0 | E20: =COUNTIFS(Exécution!$B$5:$B$239,$A20,Exécution!$I$5:$I$239,"Bloqué") -> 0 | F20: =COUNTIFS(Exécution!$B$5:$B$239,$A20,Exécution!$I$5:$I$239,"Non testé") -> 23 | G20: =IF(B20=0,0,C20/B20) -> 0
A21: Saisie et contrôles | B21: =COUNTIF(Exécution!$B$5:$B$239,A21) -> 45 | C21: =COUNTIFS(Exécution!$B$5:$B$239,$A21,Exécution!$I$5:$I$239,"OK") -> 0 | D21: =COUNTIFS(Exécution!$B$5:$B$239,$A21,Exécution!$I$5:$I$239,"KO") -> 0 | E21: =COUNTIFS(Exécution!$B$5:$B$239,$A21,Exécution!$I$5:$I$239,"Bloqué") -> 0 | F21: =COUNTIFS(Exécution!$B$5:$B$239,$A21,Exécution!$I$5:$I$239,"Non testé") -> 45 | G21: =IF(B21=0,0,C21/B21) -> 0
A22: Transmission et vérification | B22: =COUNTIF(Exécution!$B$5:$B$239,A22) -> 20 | C22: =COUNTIFS(Exécution!$B$5:$B$239,$A22,Exécution!$I$5:$I$239,"OK") -> 0 | D22: =COUNTIFS(Exécution!$B$5:$B$239,$A22,Exécution!$I$5:$I$239,"KO") -> 0 | E22: =COUNTIFS(Exécution!$B$5:$B$239,$A22,Exécution!$I$5:$I$239,"Bloqué") -> 0 | F22: =COUNTIFS(Exécution!$B$5:$B$239,$A22,Exécution!$I$5:$I$239,"Non testé") -> 20 | G22: =IF(B22=0,0,C22/B22) -> 0
A23: Missions d’inspection | B23: =COUNTIF(Exécution!$B$5:$B$239,A23) -> 7 | C23: =COUNTIFS(Exécution!$B$5:$B$239,$A23,Exécution!$I$5:$I$239,"OK") -> 0 | D23: =COUNTIFS(Exécution!$B$5:$B$239,$A23,Exécution!$I$5:$I$239,"KO") -> 0 | E23: =COUNTIFS(Exécution!$B$5:$B$239,$A23,Exécution!$I$5:$I$239,"Bloqué") -> 0 | F23: =COUNTIFS(Exécution!$B$5:$B$239,$A23,Exécution!$I$5:$I$239,"Non testé") -> 7 | G23: =IF(B23=0,0,C23/B23) -> 0
A24: Caisse et arrêtés | B24: =COUNTIF(Exécution!$B$5:$B$239,A24) -> 17 | C24: =COUNTIFS(Exécution!$B$5:$B$239,$A24,Exécution!$I$5:$I$239,"OK") -> 0 | D24: =COUNTIFS(Exécution!$B$5:$B$239,$A24,Exécution!$I$5:$I$239,"KO") -> 0 | E24: =COUNTIFS(Exécution!$B$5:$B$239,$A24,Exécution!$I$5:$I$239,"Bloqué") -> 0 | F24: =COUNTIFS(Exécution!$B$5:$B$239,$A24,Exécution!$I$5:$I$239,"Non testé") -> 17 | G24: =IF(B24=0,0,C24/B24) -> 0
A25: Trésorerie et banque | B25: =COUNTIF(Exécution!$B$5:$B$239,A25) -> 8 | C25: =COUNTIFS(Exécution!$B$5:$B$239,$A25,Exécution!$I$5:$I$239,"OK") -> 0 | D25: =COUNTIFS(Exécution!$B$5:$B$239,$A25,Exécution!$I$5:$I$239,"KO") -> 0 | E25: =COUNTIFS(Exécution!$B$5:$B$239,$A25,Exécution!$I$5:$I$239,"Bloqué") -> 0 | F25: =COUNTIFS(Exécution!$B$5:$B$239,$A25,Exécution!$I$5:$I$239,"Non testé") -> 8 | G25: =IF(B25=0,0,C25/B25) -> 0
A26: Parc automobile | B26: =COUNTIF(Exécution!$B$5:$B$239,A26) -> 24 | C26: =COUNTIFS(Exécution!$B$5:$B$239,$A26,Exécution!$I$5:$I$239,"OK") -> 0 | D26: =COUNTIFS(Exécution!$B$5:$B$239,$A26,Exécution!$I$5:$I$239,"KO") -> 0 | E26: =COUNTIFS(Exécution!$B$5:$B$239,$A26,Exécution!$I$5:$I$239,"Bloqué") -> 0 | F26: =COUNTIFS(Exécution!$B$5:$B$239,$A26,Exécution!$I$5:$I$239,"Non testé") -> 24 | G26: =IF(B26=0,0,C26/B26) -> 0
A27: Stocks de fournitures | B27: =COUNTIF(Exécution!$B$5:$B$239,A27) -> 6 | C27: =COUNTIFS(Exécution!$B$5:$B$239,$A27,Exécution!$I$5:$I$239,"OK") -> 0 | D27: =COUNTIFS(Exécution!$B$5:$B$239,$A27,Exécution!$I$5:$I$239,"KO") -> 0 | E27: =COUNTIFS(Exécution!$B$5:$B$239,$A27,Exécution!$I$5:$I$239,"Bloqué") -> 0 | F27: =COUNTIFS(Exécution!$B$5:$B$239,$A27,Exécution!$I$5:$I$239,"Non testé") -> 6 | G27: =IF(B27=0,0,C27/B27) -> 0
A28: Pilotage et rapports | B28: =COUNTIF(Exécution!$B$5:$B$239,A28) -> 15 | C28: =COUNTIFS(Exécution!$B$5:$B$239,$A28,Exécution!$I$5:$I$239,"OK") -> 0 | D28: =COUNTIFS(Exécution!$B$5:$B$239,$A28,Exécution!$I$5:$I$239,"KO") -> 0 | E28: =COUNTIFS(Exécution!$B$5:$B$239,$A28,Exécution!$I$5:$I$239,"Bloqué") -> 0 | F28: =COUNTIFS(Exécution!$B$5:$B$239,$A28,Exécution!$I$5:$I$239,"Non testé") -> 15 | G28: =IF(B28=0,0,C28/B28) -> 0
A29: Direction | B29: =COUNTIF(Exécution!$B$5:$B$239,A29) -> 3 | C29: =COUNTIFS(Exécution!$B$5:$B$239,$A29,Exécution!$I$5:$I$239,"OK") -> 0 | D29: =COUNTIFS(Exécution!$B$5:$B$239,$A29,Exécution!$I$5:$I$239,"KO") -> 0 | E29: =COUNTIFS(Exécution!$B$5:$B$239,$A29,Exécution!$I$5:$I$239,"Bloqué") -> 0 | F29: =COUNTIFS(Exécution!$B$5:$B$239,$A29,Exécution!$I$5:$I$239,"Non testé") -> 3 | G29: =IF(B29=0,0,C29/B29) -> 0
... A31: Transverse et clôture | B31: =COUNTIF(Exécution!$B$5:$B$239,A31) -> 7 | C31: =COUNTIFS(Exécution!$B$5:$B$239,$A31,Exécution!$I$5:$I$239,"OK") -> 0 | D31: =COUNTIFS(Exécution!$B$5:$B$239,$A31,Exécution!$I$5:$I$239,"KO") -> 0 | E31: =COUNTIFS(Exécution!$B$5:$B$239,$A31,Exécution!$I$5:$I$239,"Bloqué") -> 0 | F31: =COUNTIFS(Exécution!$B$5:$B$239,$A31,Exécution!$I$5:$I$239,"Non testé") -> 7 | G31: =IF(B31=0,0,C31/B31) -> 0
A32: Total | B32: =SUM(B18:B31) -> 235 | C32: =SUM(C18:C31) -> 0 | D32: =SUM(D18:D31) -> 0 | E32: =SUM(E18:E31) -> 0 | F32: =SUM(F18:F31) -> 235 | G32: =IF(B32=0,0,C32/B32) -> 0
A34: Anomalies
A35: Gravité | B35: Total | C35: Ouvertes | D35: Fermées | E35: Rejetées
A36: Bloquante | B36: =COUNTIF(Anomalies!$I$5:$I$204,A36) -> 0 | C36: =B36-D36-E36 -> 0 | D36: =COUNTIFS(Anomalies!$I$5:$I$204,A36,Anomalies!$J$5:$J$204,"Fermée") -> 0 | E36: =COUNTIFS(Anomalies!$I$5:$I$204,A36,Anomalies!$J$5:$J$204,"Rejetée") -> 0
A37: Majeure | B37: =COUNTIF(Anomalies!$I$5:$I$204,A37) -> 0 | C37: =B37-D37-E37 -> 0 | D37: =COUNTIFS(Anomalies!$I$5:$I$204,A37,Anomalies!$J$5:$J$204,"Fermée") -> 0 | E37: =COUNTIFS(Anomalies!$I$5:$I$204,A37,Anomalies!$J$5:$J$204,"Rejetée") -> 0
A38: Mineure | B38: =COUNTIF(Anomalies!$I$5:$I$204,A38) -> 0 | C38: =B38-D38-E38 -> 0 | D38: =COUNTIFS(Anomalies!$I$5:$I$204,A38,Anomalies!$J$5:$J$204,"Fermée") -> 0 | E38: =COUNTIFS(Anomalies!$I$5:$I$204,A38,Anomalies!$J$5:$J$204,"Rejetée") -> 0
A39: Évolution | B39: =COUNTIF(Anomalies!$I$5:$I$204,A39) -> 0 | C39: =B39-D39-E39 -> 0 | D39: =COUNTIFS(Anomalies!$I$5:$I$204,A39,Anomalies!$J$5:$J$204,"Fermée") -> 0 | E39: =COUNTIFS(Anomalies!$I$5:$I$204,A39,Anomalies!$J$5:$J$204,"Rejetée") -> 0
A41: Critères de sortie de la recette
A42: Tous les scénarios exécutés | B42: =IF(COUNTIF('Synthèse scénarios'!$J$5:$J$55,"Non testé")+COUNTIF('Synthèse scénarios'!$J$5:$J$55,"En cours")=0,"Atteint","Non atteint") -> Non atteint
A43: 100 % des scénarios critiques OK | B43: =IF(AND(B14>0,B13=B14),"Atteint","Non atteint") -> Non atteint
A44: Aucune anomalie bloquante ouverte | B44: =IF(C36=0,"Atteint","Non atteint") -> Atteint
A45: Aucune anomalie majeure ouverte | B45: =IF(C37=0,"Atteint","Non atteint") -> Atteint
...

Sheet Testeurs
A1: Testeurs
A2: Attribuer chaque profil de test à une personne avant la campagne
A4: Code | B4: Profil de test | C4: Rôle | D4: Profil dans l’application | E4: Nom du testeur | F4: E-mail | G4: Identifiant du compte
A5: AF | B5: Administration et Finance | C5: Comptable ou vérificateur du service central | D5: Administration et Finance
A6: AGA | B6: Agent du service A | C6: Agent qui tient la caisse du service A (par exemple 8001) | D6: Agent (service)
A7: RSA | B7: Responsable du service A | C7: Chef du service A | D7: Responsable (service)
A8: AGB | B8: Agent du service B | C8: Agent qui tient la caisse du service B (par exemple 8002) | D8: Agent (service)
A9: RSB | B9: Responsable du service B | C9: Chef du service B | D9: Responsable (service)
A10: DIR | B10: Direction | C10: Inspecteur Général ou membre de son cabinet | D10: Lecteur (Direction)
A11: PUB | B11: Personne sans compte | C11: Tiers qui reçoit un document officiel | D11: —

Sheet Exécution
A1: Exécution des scénarios
A2: Une ligne par étape · renseigner les colonnes jaunes
A4: ID | B4: Phase | C4: Scénario | D4: Priorité | E4: Étape | F4: Profil | G4: Action | H4: Résultat attendu | I4: Statut | J4: Résultat obtenu / commentaire | K4: Réf. anomalie | L4: Testeur | M4: Date
A5: UAT-01 | B5: Préparation de l’environnement | C5: Connexion d’Administration et Finance et double authentification | D5: Critique | E5: 1 | F5: AF | G5: Ouvrir l’adresse du site de recette, saisir l’identifiant et le mot de passe, cliquer sur « Se connecter ». | H5: L’application demande d’activer la double authentification (obligatoire pour A&F). | I5: Non testé
A6: UAT-01 | B6: Préparation de l’environnement | C6: Connexion d’Administration et Finance et double authentification | D6: Critique | E6: 2 | F6: AF | G6: Choisir « Utiliser plutôt une application d’authentification », scanner le code QR, saisir le code affiché, cliquer sur « Activer ». | H6: Message « Double authentification activée » ; dix codes de secours affichés. | I6: Non testé
A7: UAT-01 | B7: Préparation de l’environnement | C7: Connexion d’Administration et Finance et double authentification | D7: Critique | E7: 3 | F7: AF | G7: Imprimer ou noter les codes de secours, se déconnecter puis se reconnecter. | H7: Après le mot de passe, l’écran du code s’affiche ; le code de l’application ouvre le tableau de bord. | I7: Non testé
A8: UAT-01 | B8: Préparation de l’environnement | C8: Connexion d’Administration et Finance et double authentification | D8: Critique | E8: 4 | F8: AF | G8: Se reconnecter en utilisant un code de secours à la place du code de l’application. | H8: Connexion acceptée ; le même code de secours est refusé à la connexion suivante. | I8: Non testé
A9: UAT-02 | B9: Préparation de l’environnement | C9: Messagerie de la plateforme | D9: Critique | E9: 1 | F9: AF | G9: Ouvrir Administration › Exercice et règles de contrôle › Messagerie de la plateforme ; saisir l’adresse de la boîte, son mot de passe, le serveur et le port ; cliquer sur « Enregistrer la messagerie ». | H9: Message de confirmation ; le bandeau « Messagerie non configurée » disparaît. | I9: Non testé
A10: UAT-02 | B10: Préparation de l’environnement | C10: Messagerie de la plateforme | D10: Critique | E10: 2 | F10: AF | G10: Cliquer sur « Envoyer un e-mail de test ». | H10: L’e-mail de test arrive dans la boîte de AF (vérifier aussi les indésirables) avec le nom d’expéditeur paramétré. | I10: Non testé
A11: UAT-02 | B11: Préparation de l’environnement | C11: Messagerie de la plateforme | D11: Critique | E11: 3 | F11: AF | G11: Ouvrir le Journal d’audit. | H11: La modification de la messagerie est tracée ; le mot de passe n’y apparaît pas en clair. | I11: Non testé
A12: UAT-03 | B12: Préparation de l’environnement | C12: Référentiels : services, rubriques, nomenclature, fournisseurs | D12: Haute | E12: 1 | F12: AF | G12: Dans Référentiels › Services, renseigner le libellé et l’effectif des services A et B, puis enregistrer. | H12: Les modifications apparaissent dans la liste ; « Modification enregistrée ». | I12: Non testé
A13: UAT-03 | B13: Préparation de l’environnement | C13: Référentiels : services, rubriques, nomenclature, fournisseurs | D13: Haute | E13: 2 | F13: AF | G13: Dans l’onglet Nomenclature de l’État, ajouter la ligne 6.1.1 « Fournitures et petits matériels de bureau ». | H13: La ligne apparaît avec 0 rubrique rattachée. | I13: Non testé
A14: UAT-03 | B14: Préparation de l’environnement | C14: Référentiels : services, rubriques, nomenclature, fournisseurs | D14: Haute | E14: 3 | F14: AF | G14: Dans l’onglet Rubriques, modifier R01 : rattacher la ligne 6.1.1 et cocher les pièces exigées « Facture » et « Bon de réception ». | H14: R01 affiche la ligne de nomenclature et les pièces exigées. | I14: Non testé
A15: UAT-03 | B15: Préparation de l’environnement | C15: Référentiels : services, rubriques, nomenclature, fournisseurs | D15: Haute | E15: 4 | F15: AF | G15: Tenter de rattacher R02 à une ligne de nomenclature inexistante. | H15: Enregistrement refusé avec un message explicite. | I15: Non testé
A16: UAT-03 | B16: Préparation de l’environnement | C16: Référentiels : services, rubriques, nomenclature, fournisseurs | D16: Haute | E16: 5 | F16: AF | G16: Ajouter une rubrique de test R99, puis la désactiver. | H16: Aucun bouton de suppression ; R99 désactivée n’est plus proposée à la saisie (à vérifier en UAT-15). | I16: Non testé
... A239: UAT-51 | B239: Transverse et clôture | C239: Préparation de l’exercice suivant et conditions de clôture | D239: Moyenne | E239: 4 | F239: AF | G239: Sur le site de recette seulement : régulariser les services, clôturer l’exercice. | H239: Le solde de caisse de chaque service devient son solde initial de l’exercice suivant ; plus aucune écriture n’est possible sur l’exercice clos. | I239: Non testé

Sheet Anomalies
A1: Registre des anomalies
A2: Une ligne par anomalie · numéroter ANO-001, ANO-002…
A4: Réf. | B4: Date | C4: Testeur | D4: Scénario | E4: Étape | F4: Description | G4: Résultat attendu | H4: Résultat obtenu | I4: Gravité | J4: Statut | K4: Responsable | L4: Version corrective | M4: Date du retest | N4: Commentaire

Sheet Synthèse scénarios
A1: Synthèse par scénario
A2: Calculé automatiquement à partir de l’onglet Exécution
A4: ID | B4: Scénario | C4: Phase | D4: Priorité | E4: Étapes | F4: OK | G4: KO | H4: Bloqué | I4: Non testé | J4: Statut du scénario | K4: Anomalies ouvertes
A5: UAT-01 | B5: Connexion d’Administration et Finance et double authentification | C5: Préparation de l’environnement | D5: Critique | E5: =COUNTIF(Exécution!$A$5:$A$239,A5) -> 4 | F5: =COUNTIFS(Exécution!$A$5:$A$239,$A5,Exécution!$I$5:$I$239,"OK") -> 0 | G5: =COUNTIFS(Exécution!$A$5:$A$239,$A5,Exécution!$I$5:$I$239,"KO") -> 0 | H5: =COUNTIFS(Exécution!$A$5:$A$239,$A5,Exécution!$I$5:$I$239,"Bloqué") -> 0 | I5: =COUNTIFS(Exécution!$A$5:$A$239,$A5,Exécution!$I$5:$I$239,"Non testé") -> 4 | J5: =IF(G5>0,"KO",IF(H5>0,"Bloqué",IF(F5=E5,"OK",IF(I5=E5,"Non testé","En cours")))) -> Non testé | K5: =COUNTIFS(Anomalies!$D$5:$D$204,A5,Anomalies!$J$5:$J$204,"<>Fermée",Anomalies!$J$5:$J$204,"<>Rejetée",Anomalies!$J$5:$J$204,"<>") -> 0
A6: UAT-02 | B6: Messagerie de la plateforme | C6: Préparation de l’environnement | D6: Critique | E6: =COUNTIF(Exécution!$A$5:$A$239,A6) -> 3 | F6: =COUNTIFS(Exécution!$A$5:$A$239,$A6,Exécution!$I$5:$I$239,"OK") -> 0 | G6: =COUNTIFS(Exécution!$A$5:$A$239,$A6,Exécution!$I$5:$I$239,"KO") -> 0 | H6: =COUNTIFS(Exécution!$A$5:$A$239,$A6,Exécution!$I$5:$I$239,"Bloqué") -> 0 | I6: =COUNTIFS(Exécution!$A$5:$A$239,$A6,Exécution!$I$5:$I$239,"Non testé") -> 3 | J6: =IF(G6>0,"KO",IF(H6>0,"Bloqué",IF(F6=E6,"OK",IF(I6=E6,"Non testé","En cours")))) -> Non testé | K6: =COUNTIFS(Anomalies!$D$5:$D$204,A6,Anomalies!$J$5:$J$204,"<>Fermée",Anomalies!$J$5:$J$204,"<>Rejetée",Anomalies!$J$5:$J$204,"<>") -> 0
A7: UAT-03 | B7: Référentiels : services, rubriques, nomenclature, fournisseurs | C7: Préparation de l’environnement | D7: Haute | E7: =COUNTIF(Exécution!$A$5:$A$239,A7) -> 6 | F7: =COUNTIFS(Exécution!$A$5:$A$239,$A7,Exécution!$I$5:$I$239,"OK") -> 0 | G7: =COUNTIFS(Exécution!$A$5:$A$239,$A7,Exécution!$I$5:$I$239,"KO") -> 0 | H7: =COUNTIFS(Exécution!$A$5:$A$239,$A7,Exécution!$I$5:$I$239,"Bloqué") -> 0 | I7: =COUNTIFS(Exécution!$A$5:$A$239,$A7,Exécution!$I$5:$I$239,"Non testé") -> 6 | J7: =IF(G7>0,"KO",IF(H7>0,"Bloqué",IF(F7=E7,"OK",IF(I7=E7,"Non testé","En cours")))) -> Non testé | K7: =COUNTIFS(Anomalies!$D$5:$D$204,A7,Anomalies!$J$5:$J$204,"<>Fermée",Anomalies!$J$5:$J$204,"<>Rejetée",Anomalies!$J$5:$J$204,"<>") -> 0
A8: UAT-04 | B8: Création des comptes des testeurs | C8: Préparation de l’environnement | D8: Critique | E8: =COUNTIF(Exécution!$A$5:$A$239,A8) -> 5 | F8: =COUNTIFS(Exécution!$A$5:$A$239,$A8,Exécution!$I$5:$I$239,"OK") -> 0 | G8: =COUNTIFS(Exécution!$A$5:$A$239,$A8,Exécution!$I$5:$I$239,"KO") -> 0 | H8: =COUNTIFS(Exécution!$A$5:$A$239,$A8,Exécution!$I$5:$I$239,"Bloqué") -> 0 | I8: =COUNTIFS(Exécution!$A$5:$A$239,$A8,Exécution!$I$5:$I$239,"Non testé") -> 5 | J8: =IF(G8>0,"KO",IF(H8>0,"Bloqué",IF(F8=E8,"OK",IF(I8=E8,"Non testé","En cours")))) -> Non testé | K8: =COUNTIFS(Anomalies!$D$5:$D$204,A8,Anomalies!$J$5:$J$204,"<>Fermée",Anomalies!$J$5:$J$204,"<>Rejetée",Anomalies!$J$5:$J$204,"<>") -> 0
A9: UAT-05 | B9: Règles de contrôle et barème des missions | C9: Préparation de l’environnement | D9: Haute | E9: =COUNTIF(Exécution!$A$5:$A$239,A9) -> 4 | F9: =COUNTIFS(Exécution!$A$5:$A$239,$A9,Exécution!$I$5:$I$239,"OK") -> 0 | G9: =COUNTIFS(Exécution!$A$5:$A$239,$A9,Exécution!$I$5:$I$239,"KO") -> 0 | H9: =COUNTIFS(Exécution!$A$5:$A$239,$A9,Exécution!$I$5:$I$239,"Bloqué") -> 0 | I9: =COUNTIFS(Exécution!$A$5:$A$239,$A9,Exécution!$I$5:$I$239,"Non testé") -> 4 | J9: =IF(G9>0,"KO",IF(H9>0,"Bloqué",IF(F9=E9,"OK",IF(I9=E9,"Non testé","En cours")))) -> Non testé | K9: =COUNTIFS(Anomalies!$D$5:$D$204,A9,Anomalies!$J$5:$J$204,"<>Fermée",Anomalies!$J$5:$J$204,"<>Rejetée",Anomalies!$J$5:$J$204,"<>") -> 0
A10: UAT-06 | B10: Première connexion et choix du mot de passe | C10: Accès et sécurité | D10: Critique | E10: =COUNTIF(Exécution!$A$5:$A$239,A10) -> 4 | F10: =COUNTIFS(Exécution!$A$5:$A$239,$A10,Exécution!$I$5:$I$239,"OK") -> 0 | G10: =COUNTIFS(Exécution!$A$5:$A$239,$A10,Exécution!$I$5:$I$239,"KO") -> 0 | H10: =COUNTIFS(Exécution!$A$5:$A$239,$A10,Exécution!$I$5:$I$239,"Bloqué") -> 0 | I10: =COUNTIFS(Exécution!$A$5:$A$239,$A10,Exécution!$I$5:$I$239,"Non testé") -> 4 | J10: =IF(G10>0,"KO",IF(H10>0,"Bloqué",IF(F10=E10,"OK",IF(I10=E10,"Non testé","En cours")))) -> Non testé | K10: =COUNTIFS(Anomalies!$D$5:$D$204,A10,Anomalies!$J$5:$J$204,"<>Fermée",Anomalies!$J$5:$J$204,"<>Rejetée",Anomalies!$J$5:$J$204,"<>") -> 0
A11: UAT-07 | B11: Activation par invitation e-mail | C11: Accès et sécurité | D11: Haute | E11: =COUNTIF(Exécution!$A$5:$A$239,A11) -> 4 | F11: =COUNTIFS(Exécution!$A$5:$A$239,$A11,Exécution!$I$5:$I$239,"OK") -> 0 | G11: =COUNTIFS(Exécution!$A$5:$A$239,$A11,Exécution!$I$5:$I$239,"KO") -> 0 | H11: =COUNTIFS(Exécution!$A$5:$A$239,$A11,Exécution!$I$5:$I$239,"Bloqué") -> 0 | I11: =COUNTIFS(Exécution!$A$5:$A$239,$A11,Exécution!$I$5:$I$239,"Non testé") -> 4 | J11: =IF(G11>0,"KO",IF(H11>0,"Bloqué",IF(F11=E11,"OK",IF(I11=E11,"Non testé","En cours")))) -> Non testé | K11: =COUNTIFS(Anomalies!$D$5:$D$204,A11,Anomalies!$J$5:$J$204,"<>Fermée",Anomalies!$J$5:$J$204,"<>Rejetée",Anomalies!$J$5:$J$204,"<>") -> 0
A12: UAT-08 | B12: Verrouillage, inactivité et mot de passe oublié | C12: Accès et sécurité | D12: Haute | E12: =COUNTIF(Exécution!$A$5:$A$239,A12) -> 5 | F12: =COUNTIFS(Exécution!$A$5:$A$239,$A12,Exécution!$I$5:$I$239,"OK") -> 0 | G12: =COUNTIFS(Exécution!$A$5:$A$239,$A12,Exécution!$I$5:$I$239,"KO") -> 0 | H12: =COUNTIFS(Exécution!$A$5:$A$239,$A12,Exécution!$I$5:$I$239,"Bloqué") -> 0 | I12: =COUNTIFS(Exécution!$A$5:$A$239,$A12,Exécution!$I$5:$I$239,"Non testé") -> 5 | J12: =IF(G12>0,"KO",IF(H12>0,"Bloqué",IF(F12=E12,"OK",IF(I12=E12,"Non testé","En cours")))) -> Non testé | K12: =COUNTIFS(Anomalies!$D$5:$D$204,A12,Anomalies!$J$5:$J$204,"<>Fermée",Anomalies!$J$5:$J$204,"<>Rejetée",Anomalies!$J$5:$J$204,"<>") -> 0
A13: UAT-09 | B13: Double authentification par e-mail pour un compte de service | C13: Accès et sécurité | D13: Moyenne | E13: =COUNTIF(Exécution!$A$5:$A$239,A13) -> 4 | F13: =COUNTIFS(Exécution!$A$5:$A$239,$A13,Exécution!$I$5:$I$239,"OK") -> 0 | G13: =COUNTIFS(Exécution!$A$5:$A$239,$A13,Exécution!$I$5:$I$239,"KO") -> 0 | H13: =COUNTIFS(Exécution!$A$5:$A$239,$A13,Exécution!$I$5:$I$239,"Bloqué") -> 0 | I13: =COUNTIFS(Exécution!$A$5:$A$239,$A13,Exécution!$I$5:$I$239,"Non testé") -> 4 | J13: =IF(G13>0,"KO",IF(H13>0,"Bloqué",IF(F13=E13,"OK",IF(I13=E13,"Non testé","En cours")))) -> Non testé | K13: =COUNTIFS(Anomalies!$D$5:$D$204,A13,Anomalies!$J$5:$J$204,"<>Fermée",Anomalies!$J$5:$J$204,"<>Rejetée",Anomalies!$J$5:$J$204,"<>") -> 0
A14: UAT-10 | B14: Cloisonnement des données entre services et profils | C14: Accès et sécurité | D14: Critique | E14: =COUNTIF(Exécution!$A$5:$A$239,A14) -> 5 | F14: =COUNTIFS(Exécution!$A$5:$A$239,$A14,Exécution!$I$5:$I$239,"OK") -> 0 | G14: =COUNTIFS(Exécution!$A$5:$A$239,$A14,Exécution!$I$5:$I$239,"KO") -> 0 | H14: =COUNTIFS(Exécution!$A$5:$A$239,$A14,Exécution!$I$5:$I$239,"Bloqué") -> 0 | I14: =COUNTIFS(Exécution!$A$5:$A$239,$A14,Exécution!$I$5:$I$239,"Non testé") -> 5 | J14: =IF(G14>0,"KO",IF(H14>0,"Bloqué",IF(F14=E14,"OK",IF(I14=E14,"Non testé","En cours")))) -> Non testé | K14: =COUNTIFS(Anomalies!$D$5:$D$204,A14,Anomalies!$J$5:$J$204,"<>Fermée",Anomalies!$J$5:$J$204,"<>Rejetée",Anomalies!$J$5:$J$204,"<>") -> 0
A15: UAT-11 | B15: Budget et solde initial du service | C15: Budget et fonds | D15: Critique | E15: =COUNTIF(Exécution!$A$5:$A$239,A15) -> 5 | F15: =COUNTIFS(Exécution!$A$5:$A$239,$A15,Exécution!$I$5:$I$239,"OK") -> 0 | G15: =COUNTIFS(Exécution!$A$5:$A$239,$A15,Exécution!$I$5:$I$239,"KO") -> 0 | H15: =COUNTIFS(Exécution!$A$5:$A$239,$A15,Exécution!$I$5:$I$239,"Bloqué") -> 0 | I15: =COUNTIFS(Exécution!$A$5:$A$239,$A15,Exécution!$I$5:$I$239,"Non testé") -> 5 | J15: =IF(G15>0,"KO",IF(H15>0,"Bloqué",IF(F15=E15,"OK",IF(I15=E15,"Non testé","En cours")))) -> Non testé | K15: =COUNTIFS(Anomalies!$D$5:$D$204,A15,Anomalies!$J$5:$J$204,"<>Fermée",Anomalies!$J$5:$J$204,"<>Rejetée",Anomalies!$J$5:$J$204,"<>") -> 0
A16: UAT-12 | B16: Remise d’une avance de fonds | C16: Budget et fonds | D16: Critique | E16: =COUNTIF(Exécution!$A$5:$A$239,A16) -> 5 | F16: =COUNTIFS(Exécution!$A$5:$A$239,$A16,Exécution!$I$5:$I$239,"OK") -> 0 | G16: =COUNTIFS(Exécution!$A$5:$A$239,$A16,Exécution!$I$5:$I$239,"KO") -> 0 | H16: =COUNTIFS(Exécution!$A$5:$A$239,$A16,Exécution!$I$5:$I$239,"Bloqué") -> 0 | I16: =COUNTIFS(Exécution!$A$5:$A$239,$A16,Exécution!$I$5:$I$239,"Non testé") -> 5 | J16: =IF(G16>0,"KO",IF(H16>0,"Bloqué",IF(F16=E16,"OK",IF(I16=E16,"Non testé","En cours")))) -> Non testé | K16: =COUNTIFS(Anomalies!$D$5:$D$204,A16,Anomalies!$J$5:$J$204,"<>Fermée",Anomalies!$J$5:$J$204,"<>Rejetée",Anomalies!$J$5:$J$204,"<>") -> 0
... A55: UAT-51 | B55: Préparation de l’exercice suivant et conditions de clôture | C55: Transverse et clôture | D55: Moyenne | E55: =COUNTIF(Exécution!$A$5:$A$239,A55) -> 4 | F55: =COUNTIFS(Exécution!$A$5:$A$239,$A55,Exécution!$I$5:$I$239,"OK") -> 0 | G55: =COUNTIFS(Exécution!$A$5:$A$239,$A55,Exécution!$I$5:$I$239,"KO") -> 0 | H55: =COUNTIFS(Exécution!$A$5:$A$239,$A55,Exécution!$I$5:$I$239,"Bloqué") -> 0 | I55: =COUNTIFS(Exécution!$A$5:$A$239,$A55,Exécution!$I$5:$I$239,"Non testé") -> 4 | J55: =IF(G55>0,"KO",IF(H55>0,"Bloqué",IF(F55=E55,"OK",IF(I55=E55,"Non testé","En cours")))) -> Non testé | K55: =COUNTIFS(Anomalies!$D$5:$D$204,A55,Anomalies!$J$5:$J$204,"<>Fermée",Anomalies!$J$5:$J$204,"<>Rejetée",Anomalies!$J$5:$J$204,"<>") -> 0
